Workbook

Sheet Allocation of Jan-26 
B1: Cost of placement | C1: FV of placement | D1: Closing Balance as at Dec'25 | E1: Closing Balance - (31-Jan-2026) | F1: Concentration (%) - (31-Jan-2026) | G1: Revised Placement | H1: Concentration (%) | I1: Holding Period | J1: Days to Maturity | K1: Weighted Maturity | L1: Placement % | M1: Weighted Placements
A2: MTBs (1Y) | B2: 1999988012 | C2: 2.0572194e+09 | D2: =C2 -> 2057219450 | E2: 2.1114701e+09 | F2: =C2/$E$13 -> 0.21955012 | G2: =D2 -> 2057219450 | H2: =E2/$E$13 -> 0.22533985 | I2: 31 | J2: =218-I2 -> 187 | K2: =C2/SUM($E$2:$E$12)*J2 -> 41.055873 | L2: =I2/31 -> 1 | M2: =E2*L2 -> 2111470084
A3: MTBs (3M) | B3: 487745500 | C3: =B3 -> 487745500 | D3: =C3 -> 487745500 | E3: 4.9255976e+08 | F3: =C3/$E$13 -> 0.052053069 | G3: =E3 -> 4.9255976e+08 | H3: =E3/$E$13 -> 0.052566855 | I3: 31 | J3: =64-I3 -> 33 | K3: =C3/SUM($E$2:$E$12)*J3 -> 1.7177513 | L3: =I3/31 -> 1 | M3: =E3*L3 -> 4.9255976e+08
A4: MTBs (6M) | B4: 474182500 | C4: =B4 -> 474182500 | D4: =C4 -> 474182500 | E4: 4.9276545e+08 | F4: =C4/$E$13 -> 0.050605601 | G4: =E4 -> 492765455 | H4: =E4/$E$13 -> 0.052588807 | I4: 31 | J4: =162-I4 -> 131 | K4: =C4/SUM($E$2:$E$12)*J4 -> 6.6293338 | L4: =I4/31 -> 1 | M4: =E4*L4 -> 492765455
A5: Faysal Bank | B5: 1601144278 | C5: 1055368872 | D5: =C5 -> 1055368872 | E5: 3020864339 | F5: =C5/$E$13 -> 0.11263085 | G5: 2000000000 | H5: =E5/$E$13 -> 0.32239202 | I5: 31 | J5: 0 | K5: =C5/SUM($E$2:$E$12)*J5 -> 0 | L5: =I5/31 -> 1 | M5: =E5*L5 -> 3020864339
A6: Samba Bank | B6: 1329131526 | C6: 1028157070 | D6: =C6 -> 1028157070 | E6: 556124.26 | F6: =C6/$E$13 -> 0.10972675 | G6: =E6 -> 556124.26 | H6: =E6/$E$13 -> 5.9350572e-05 | I6: 31 | J6: 0 | K6: =C6/SUM($E$2:$E$12)*J6 -> 0 | L6: =I6/31 -> 1 | M6: =E6*L6 -> 556124.26
A7: TDR | B7: 1000000000 | C7: 1000000000 | D7: =C7 -> 1000000000 | E7: 0 | F7: =C7/$E$13 -> 0.10672178 | G7: =E7 -> 0 | H7: =E7/$E$13 -> 0 | I7: 31 | J7: 0 | K7: =C7/SUM($E$2:$E$12)*J7 -> 0 | L7: =I7/31 -> 1 | M7: =E7*L7 -> 0
A8: COI | B8: 1300000000 | C8: 1300000000 | D8: =C8 -> 1300000000 | E8: =D8 -> 1300000000 | F8: =C8/$E$13 -> 0.13873832 | G8: =E8 -> 1300000000 | H8: =E8/$E$13 -> 0.13873832 | I8: 31 | J8: 30 | K8: =C8/SUM($E$2:$E$12)*J8 -> 4.1621495 | L8: =I8/31 -> 1 | M8: =E8*L8 -> 1300000000
A9: Alfalah Government Securities Fund Plan II | B9: 816606719 | C9: 827108187 | D9: =C9 -> 827108187 | E9: 833081692 | F9: =C9/$E$13 -> 0.088270459 | G9: =E9 -> 833081692 | H9: =E9/$E$13 -> 0.088907962 | I9: 31 | J9: 271 | K9: =C9/SUM($E$2:$E$12)*J9 -> 23.921294 | L9: =I9/31 -> 1 | M9: =E9*L9 -> 833081692
A10: Alfalah MTS Fund (Formerly: Faysal MTS Fund) | B10: 303753987 | C10: 306538002 | D10: =C10 -> 306538002 | E10: 309361746 | F10: =C10/$E$13 -> 0.032714282 | G10: =E10 -> 309361746 | H10: =E10/$E$13 -> 0.033015637 | I10: 31 | J10: 0 | K10: =C10/SUM($E$2:$E$12)*J10 -> 0 | L10: =I10/31 -> 1 | M10: =E10*L10 -> 309361746
A11: Alfalah Income Multiplier | E11: 0 | F11: =C11/$E$13 -> 0 | G11: =D23*0.3 -> 300000000 | H11: =E11/$E$13 -> 0 | I11: 31 | J11: 0 | K11: =C11/SUM($E$2:$E$12)*J11 -> 0 | L11: =I11/31 -> 1 | M11: =E11*L11 -> 0
A12: MCB Investment Saving Plan I | B12: 800000000 | C12: 802654992 | D12: =C12 -> 802654992 | E12: 8.0949922e+08 | F12: =C12/$E$13 -> 0.085660771 | G12: =E12 -> 8.0949922e+08 | H12: =E12/$E$13 -> 0.086391199 | I12: 31 | J12: 1 | K12: =C12/SUM($E$2:$E$12)*J12 -> 0.085660771 | L12: =I12/31 -> 1 | M12: =E12*L12 -> 8.0949922e+08
A13: Total Income | C13: =SUM(C2:C12) -> 9338974573 | D13: =SUM(D2:D12) -> 9338974573 | E13: =SUM(E2:E12) -> 9370158424 | F13: =SUM(F2:F12) -> 0.996672 | G13: =SUM(G2:G12) -> 8595043451 | H13: =SUM(H2:H12) -> 1 | K13: =SUM(K2:K12) -> 77.572063 | M13: =SUM(M2:M12) -> 9370158424
B16: Finance Cost
B17: =10.63%-C17 -> 0.1058 | C17: 0.0005 | K17: 1300 | L17: 0.1005 | M17: =L17*K17 -> 130.65
K18: 1238 | L18: 0.1075 | M18: =L18*K18 -> 133.085
C19: Funds Available | D19: =D5+D6+D7 -> 3083525942 | I19: bench | K19: 1238 | L19: =B17 -> 0.1058 | M19: =L19*K19 -> 130.9804
C20: Funds in Samba for operations | D20: =D19-D21 -> 83525942 | E20: (will be moved to Faysal in this week) | L20: =L18-L19 -> 0.0017 | M20: =M17+M18-M19 -> 132.7546
B21: Currently | C21: Placement in Faysal | D21: 3000000000 | M21: =M20/K17 -> 0.10211892
C22: Faysal Saving Account @ 10.25% | D22: 2000000000 | M22: =M21-10.38% -> -0.0016810769
C23: Allocation Available | D23: =D21-D22 -> 1000000000
D25: % to Total Portfolio
A26: Exposure in Alfalah | B26: Current | C26: =G9+G10 -> 1142443438 | D26: =C26/G13 -> 0.13291887 | I26: 2019-20 (12m) | J26: 2020-21 (12m) | K26: 2021-22 (12m) | L26: 2022-23 (12m) | M26: 2023-24 (12m) | N26: 2024-25 (12m) | O26: July-Nov 2025 (5m)
B27: Additional Investment | C27: =C26+G11 -> 1442443438 | D27: =C27/G13 -> 0.1678227 | I27: 13066 | J27: 16694 | K27: 24891 | L27: 52779 | M27: 37386 | N27: 48905 | O27: 5167
I28: 83 | J28: 104 | K28: 140 | L28: 213 | M28: 132 | N28: 175 | O28: 18
I29: 158 | J29: 160 | K29: 177 | L29: 248 | M29: 283 | N29: 279 | O29: 282

Sheet Allocation Strategy
B2: Current | I2: Allocation Available
B3: Allocation Available (PKR'Mn) | D3: =J8 -> 3000 | I3: TDR | J3: 1000
B4: Month | D4: 1 | I4: Faysal - Saving | J4: 1058
I5: Samba - Saving | J5: 1022
B6: Particular | C6: % of Allocation | D6: Rate | E6: Amount (PKR'Mn) | G6: Reason | I6: Available Allocation | J6: =SUM(J3:J5) -> 3080
B7: Faysal Saving | C7: =E7/$D$3 -> 1 | D7: 0.1025 | E7: =J8 -> 3000 | F7: =E7*(D7*1/12) -> 25.625 | G7: Keep the funds till MPC | I7: Operating Cost | J7: -80
B8: Income Multiplier | C8: =E8/$D$3 -> 0 | D8: 0.107 | E8: 0 | F8: =E8*(D8*1/12) -> 0 | G8: Investment in Mutual Fund | J8: =J6+J7 -> 3000
B9: Sovereign Fund / GSF | C9: =E9/$D$3 -> 0 | D9: 0.105 | E9: 0 | F9: =E9*(D9*1/12) -> 0 | G9: Investment in Mutual Fund
B10: 12 MTB | C10: =E10/$D$3 -> 0 | D10: 0.1014 | E10: 0 | F10: =E10*(D10*1/12) -> 0 | G10: Placement in 3MTBs directly | J10: Rates | K10: Amount | L10: Annualized | M10: Monthly
B11: 3 MTBs | C11: =E11/$D$3 -> 0 | D11: 0.1005 | E11: 0 | F11: =E11*(D11*1/12) -> 0 | I11: Finance Cost | J11: 0.1058 | K11: -1238 | L11: =(K11*J11) -> -130.9804 | M11: =K11*J11*1/12 -> -10.915033
B12: MCB Pakistan Sovereign Fund | C12: =E12/$D$3 -> 0 | D12: 0.1025 | I12: COI (Placement) | J12: 0.1005 | K12: 1300 | L12: =(K12*J12) -> 130.65 | M12: =K12*J12*1/12 -> 10.8875
B13: Total | C13: =SUM(C7:C10) -> 1 | E13: =SUM(E7:E11) -> 3000 | F13: =SUM(F7:F11)+F186 -> 25.625 | J13: =J12-J11 -> -0.0053 | L13: =L11+L12 -> -0.3304 | M13: =M11+M12 -> -0.027533333
B14: Avg return | F14: =(F13/E13)*12/1 -> 0.1025
I15: Currently Placement
B16: Recommendation - 1 | C16: Allocation Available | E16: 1000 | I16: Faysal Saving Account | J16: =F14 -> 0.1025 | K16: =E13 -> 3000 | L16: =K16*J16 -> 307.5 | M16: =L16*1/12 -> 25.625
B17: Faysal Saving Account | C17: =E17/E23 -> 0.9 | D17: 0.1025 | E17: =(D3-E18) -> 2700 | F17: =E17*(D17*1/12) -> 23.0625 | G17: Keep the funds till MPC | I17: Total Placement (Including COIs) | K17: =K16+K12 -> 4300
B18: Income Multiplier | C18: =E18/$D$3 -> 0.1 | D18: 0.107 | E18: =E16*0.3 -> 300 | F18: =E18*(D18*1/12) -> 2.675 | G18: Diversify investment in MF for Yield of 50bps | I18: Total Income (Including COIs) | L18: =L16+L12 -> 438.15 | M18: =M16+M12 -> 36.5125
B19: Sovereign Fund / GSF | C19: =E19/$D$3 -> 0 | D19: 0.105 | E19: 0 | F19: =E19*(D19*1/12) -> 0 | I19: Expense | L19: =L11 -> -130.9804 | M19: =M11 -> -10.915033
B20: 12 MTB | C20: =E20/$D$3 -> 0 | D20: 0.1014 | E20: 0 | F20: =E20*(D20*1/12) -> 0 | I20: Net Carry (Amount) | L20: =L18+L19 -> 307.1696 | M20: =M18+M19 -> 25.597467
B21: AKD Aggressive Income Fund | C21: =E21/$D$3 -> 0 | D21: 0.1005 | E21: 0 | F21: =E21*(D21*1/12) -> 0 | G21: Diversify investment in MF for Yield of 50bps | I21: Net Carry (%) | L21: =L20/K17 -> 0.071434791 | M21: =(M20/K17)*12/1 -> 0.071434791
B22: 3 MTBs | C22: =E22/$D$3 -> 0 | D22: 0.1025 | E22: 0 | F22: =E22*(D22*1/12) -> 0
B23: Total | C23: =SUM(C17:C20) -> 1 | E23: =SUM(E17:E22) -> 3000 | F23: =SUM(F17:F21)+F195 -> 25.7375 | I23: Recommendation - 1
B24: Avg return | F24: =(F23/E23)*12/1 -> 0.10295 | I24: Faysal Saving | J24: =J16 -> 0.1025 | K24: =E17 -> 2700 | L24: =K24*J24 -> 276.75 | M24: =L24*1/12 -> 23.0625
I25: =B18 -> Income Multiplier | J25: =D18 -> 0.107 | K25: =E18 -> 300 | L25: =K25*J25 -> 32.1 | M25: =L25*1/12 -> 2.675
B26: Recommendation - 2 | C26: Allocation Available | E26: 1000 | I26: Total Placement (Including COIs) | K26: =K24+K25+K12 -> 4300
B27: Faysal Saving Account | C27: =E27/E33 -> 0.66666667 | D27: 0.1025 | E27: =D3-E26 -> 2000 | F27: =E27*(D27*1/12) -> 17.083333 | G27: Keep the funds till MPC | I27: Total Income (Including COIs) | L27: =L24+L25+L12 -> 439.5 | M27: =L27*1/12 -> 36.625
B28: Income Multiplier | C28: =E28/$D$3 -> 0.1 | D28: 0.107 | E28: =E26*0.3 -> 300 | F28: =E28*(D28*1/12) -> 2.675 | G28: Diversify investment in MF for Yield of 50bps | I28: Expense | L28: =L11 -> -130.9804 | M28: =L28*1/12 -> -10.915033
B29: Sovereign Fund / GSF | C29: =E29/$D$3 -> 0 | D29: 0.105 | E29: 0 | F29: =E29*(D29*1/12) -> 0 | I29: Net Carry (Amount) | L29: =L27+L28 -> 308.5196 | M29: =L29*1/12 -> 25.709967
B30: 12 MTB | C30: =E30/$D$3 -> 0 | D30: 0.1014 | E30: 0 | F30: =E30*(D30*1/12) -> 0 | I30: Net Carry (%) | L30: =L29/K26 -> 0.071748744 | M30: =M29/K26*12/1 -> 0.071748744
B31: AKD Aggressive Income Fund | C31: =E31/$D$3 -> 0.23333333 | D31: 0.107 | E31: 700 | F31: =E31*(D31*1/12) -> 6.2416667 | G31: Diversify investment in MF for Yield of 50bps
B32: 3 MTBs | D32: 0.1025 | I32: Recommendation - 2
B33: Total | C33: =SUM(C27:C30) -> 0.76666667 | E33: =SUM(E27:E31) -> 3000 | F33: =SUM(F27:F31)+F206 -> 26 | I33: Faysal Saving | J33: =D27 -> 0.1025 | K33: =E27 -> 2000 | L33: =K33*J33 -> 205 | M33: =L33*1/12 -> 17.083333
B34: Avg return | F34: =(F33/E33)*12/1 -> 0.104 | I34: =B28 -> Income Multiplier | J34: =D28 -> 0.107 | K34: =E28 -> 300 | L34: =K34*J34 -> 32.1 | M34: =L34*1/12 -> 2.675
B35: *Diversified the Fund due to a total exposure on Alfalah will increase to 15% of portfolio | I35: =B31 -> AKD Aggressive Income Fund | J35: =D29 -> 0.105 | K35: =E31 -> 700 | L35: =K35*J35 -> 73.5 | M35: =L35*1/12 -> 6.125
I36: =I26 -> Total Placement (Including COIs) | K36: =K33+K34+K35+K12 -> 4300 | L36: =L35+L34+L33+L12 -> 441.25 | M36: =L36*1/12 -> 36.770833
B37: Recommendation - 3 | C37: Allocation Available | E37: 1000
B38: Faysal Saving Account | C38: =E38/E45 -> 0.65217391 | D38: 0.1025 | E38: =E13-E37-E44 -> 1500 | F38: =E38*(D38*1/12) -> 12.8125 | G38: Keep the funds till MPC | I38: Total Income (Including COIs) | L38: =L36 -> 441.25 | M38: =L38*1/12 -> 36.770833
B39: Income Multiplier | C39: =E39/$D$3 -> 0.1 | D39: 0.107 | E39: =E37*0.3 -> 300 | F39: =E39*(D39*1/12) -> 2.675 | G39: Diversify investment in MF for Yield of 50bps | I39: Expense | L39: =L11 -> -130.9804 | M39: =L39*1/12 -> -10.915033
B40: Sovereign Fund / GSF | C40: =E40/$D$3 -> 0 | D40: 0.105 | E40: 0 | F40: =E40*(D40*1/12) -> 0 | I40: Net Carry (Amount) | L40: =L38+L39 -> 310.2696 | M40: =L40*1/12 -> 25.8558
B41: 12 MTB | C41: =E41/$D$3 -> 0 | D41: 0.1014 | E41: 0 | F41: =E41*(D41*1/12) -> 0 | I41: Net Carry (%) | L41: =L40/K36 -> 0.072155721 | M41: =M40/K36*12/1 -> 0.072155721
...

Sheet Jan-26 
B1: Cost of placement | C1: FV of placement | D1: Closing Balance as at Dec'25 | E1: New Placements - (12-Jan-2026) | F1: Concentration (%) - (12-Jan-2026) | G1: Revised Placement | H1: Concentration (%) | I1: Holding Period | J1: Days to Maturity | K1: Weighted Maturity | L1: Placement % | M1: Weighted Placements
A2: MTBs (1Y) | B2: 1999988012 | C2: 2.0572194e+09 | D2: =C2 -> 2057219450 | E2: =D2 -> 2057219450 | F2: =C2/$E$14 -> 0.22028323 | G2: =D2 -> 2057219450 | H2: =E2/$E$14 -> 0.22028323 | I2: 31 | J2: 187 | K2: =C2/SUM($E$2:$E$13)*J2 -> 41.192963 | L2: =I2/31 -> 1 | M2: =E2*L2 -> 2057219450
A3: MTBs (3M) | B3: 487745500 | C3: =B3 -> 487745500 | D3: =C3 -> 487745500 | E3: =D3 -> 487745500 | F3: =C3/$E$14 -> 0.05222688 | G3: =E3 -> 487745500 | H3: =E3/$E$14 -> 0.05222688 | I3: 31 | J3: 33 | K3: =C3/SUM($E$2:$E$13)*J3 -> 1.723487 | L3: =I3/31 -> 1 | M3: =E3*L3 -> 487745500
A4: MTBs (6M) | B4: 474182500 | C4: =B4 -> 474182500 | D4: =C4 -> 474182500 | E4: =D4 -> 474182500 | F4: =C4/$E$14 -> 0.050774579 | G4: =E4 -> 474182500 | H4: =E4/$E$14 -> 0.050774579 | I4: 31 | J4: 131 | K4: =C4/SUM($E$2:$E$13)*J4 -> 6.6514698 | L4: =I4/31 -> 1 | M4: =E4*L4 -> 474182500
A5: Faysal Bank | B5: 1601144278 | C5: 1055368872 | D5: =C5 -> 1055368872 | E5: =(D5+D6+D7)-E6 -> 3000000000 | F5: =C5/$E$14 -> 0.11300693 | G5: 2000000000 | H5: =E5/$E$14 -> 0.32123441 | I5: 31 | J5: 0 | K5: =C5/SUM($E$2:$E$13)*J5 -> 0 | L5: =I5/31 -> 1 | M5: =E5*L5 -> 3000000000
A6: Samba Bank | B6: 1329131526 | C6: 1028157070 | D6: =C6 -> 1028157070 | E6: 83525942 | F6: =C6/$E$14 -> 0.11009314 | G6: =E6 -> 83525942 | H6: =E6/$E$14 -> 0.0089438023 | I6: 31 | J6: 0 | K6: =C6/SUM($E$2:$E$13)*J6 -> 0 | L6: =I6/31 -> 1 | M6: =E6*L6 -> 83525942
A7: TDR | B7: 1000000000 | C7: 1000000000 | D7: =C7 -> 1000000000 | E7: 0 | F7: =C7/$E$14 -> 0.10707814 | G7: =E7 -> 0 | H7: =E7/$E$14 -> 0 | I7: 31 | J7: 0 | K7: =C7/SUM($E$2:$E$13)*J7 -> 0 | L7: =I7/31 -> 1 | M7: =E7*L7 -> 0
A8: COI | B8: 1300000000 | C8: 1300000000 | D8: =C8 -> 1300000000 | E8: =D8 -> 1300000000 | F8: =C8/$E$14 -> 0.13920158 | G8: =E8 -> 1300000000 | H8: =E8/$E$14 -> 0.13920158 | I8: 31 | J8: 30 | K8: =C8/SUM($E$2:$E$13)*J8 -> 4.1760473 | L8: =I8/31 -> 1 | M8: =E8*L8 -> 1300000000
A9: Alfalah Government Securities Fund Plan II | B9: 816606719 | C9: 827108187 | D9: =C9 -> 827108187 | E9: =D9 -> 827108187 | F9: =C9/$E$14 -> 0.088565204 | G9: =E9 -> 827108187 | H9: =E9/$E$14 -> 0.088565204 | I9: 31 | J9: 0 | K9: =C9/SUM($E$2:$E$13)*J9 -> 0 | L9: =I9/31 -> 1 | M9: =E9*L9 -> 827108187
A10: Alfalah MTS Fund (Formerly: Faysal MTS Fund) | B10: 303753987 | C10: 306538002 | D10: =C10 -> 306538002 | E10: =D10 -> 306538002 | F10: =C10/$E$14 -> 0.032823518 | G10: =E10 -> 306538002 | H10: =E10/$E$14 -> 0.032823518 | I10: 31 | J10: 0 | K10: =C10/SUM($E$2:$E$13)*J10 -> 0 | L10: =I10/31 -> 1 | M10: =E10*L10 -> 306538002
A11: Alfalah Income Multiplier | B11: 500000000 | E11: 0 | F11: =C11/$E$14 -> 0 | G11: =D24*0.3 -> 300000000 | H11: =E11/$E$14 -> 0 | I11: 31 | J11: 0 | K11: =C11/SUM($E$2:$E$13)*J11 -> 0 | L11: =I11/31 -> 1 | M11: =E11*L11 -> 0
A12: MCB Investment Saving Plan I | B12: 800000000 | C12: 802654992 | D12: =C12 -> 802654992 | E12: =D12 -> 802654992 | F12: =C12/$E$14 -> 0.085946801 | G12: =E12 -> 802654992 | H12: =E12/$E$14 -> 0.085946801 | I12: 31 | J12: 0 | K12: =C12/SUM($E$2:$E$13)*J12 -> 0 | L12: =I12/31 -> 1 | M12: =E12*L12 -> 802654992
A13: AKD Aggressive Fund | E13: 0 | F13: =C13/$E$14 -> 0 | G13: =D24*0.7 -> 700000000 | H13: =E13/$E$14 -> 0 | I13: 31 | J13: 0 | K13: =C13/SUM($E$2:$E$13)*J13 -> 0
A14: Total Income | C14: =SUM(C2:C12) -> 9338974573 | D14: =SUM(D2:D12) -> 9338974573 | E14: =SUM(E2:E12) -> 9338974573 | F14: =SUM(F2:F12) -> 1 | G14: =SUM(G2:G13) -> 9338974573 | H14: =SUM(H2:H12) -> 1 | K14: =SUM(K2:K12) -> 53.743968 | M14: =SUM(M2:M12) -> 9338974573
E15: =E14-D14 -> 0
C16: =C2-B2 -> 57231438 | D16: =SUM(D2:D4) -> 3019147450
B17: Finance Cost
B18: =10.63%-C18 -> 0.1058 | C18: 0.0005 | K18: 1300 | L18: 0.1005 | M18: =L18*K18 -> 130.65
K19: 1238 | L19: 0.1075 | M19: =L19*K19 -> 133.085
C20: Funds Available | D20: =D5+D6+D7 -> 3083525942 | I20: bench | K20: 1238 | L20: =B18 -> 0.1058 | M20: =L20*K20 -> 130.9804
C21: Funds in Samba for operations | D21: =D20-D22 -> 83525942 | E21: (will be moved to Faysal in this week) | L21: =L19-L20 -> 0.0017 | M21: =M18+M19-M20 -> 132.7546
B22: Currently | C22: Placement in Faysal | D22: 3000000000 | M22: =M21/K18 -> 0.10211892
C23: Faysal Saving Account @ 10.25% | D23: 2000000000 | M23: =M22-10.38% -> -0.0016810769
C24: Allocation Available | D24: =D22-D23 -> 1000000000
D26: % to Total Portfolio
A27: Exposure in Alfalah | B27: Current | C27: =G9+G10 -> 1133646189 | D27: =C27/G14 -> 0.12138872 | I27: 2019-20 (12m) | J27: 2020-21 (12m) | K27: 2021-22 (12m) | L27: 2022-23 (12m) | M27: 2023-24 (12m) | N27: 2024-25 (12m) | O27: July-Nov 2025 (5m)
B28: Additional Investment | C28: =C27+G11 -> 1433646189 | D28: =C28/G14 -> 0.15351216 | I28: 13066 | J28: 16694 | K28: 24891 | L28: 52779 | M28: 37386 | N28: 48905 | O28: 5167
I29: 83 | J29: 104 | K29: 140 | L29: 213 | M29: 132 | N29: 175 | O29: 18
I30: 158 | J30: 160 | K30: 177 | L30: 248 | M30: 283 | N30: 279 | O30: 282

Sheet Post MPC Allocation Strategy
B2: Qtr End | C2: =C3+90 -> 46199
B3: Date | C3: =TODAY() -> 46109 | K3: =B9 -> NIT Income Fund
B4: Allocation Available (PKR'Mn) | C4: 3000 | K4: Asset Classes | L4: Allocation % | M4: Amount (PKR) | N4: Rate of Profit | O4: WAM
K5: Govt Securities (Treasury Bills) | L5: 0.0988 | M5: 242197200 | N5: 0.1 | O5: 118
B6: Particular | C6: % of Allocation | D6: Rate | E6: Maturity | F6: Amount (PKR'Mn) | G6: Interest Earned | K6: Govt Securities (PIBs Fixed) | L6: 0.0769 | M6: 188310300 | N6: 0.0998 | O6: 460
B7: Faysal Saving | C7: =F7/$F$13 -> 0 | D7: 0.102 | E7: 0 | F7: 0 | G7: =F7*(D7*($C$2-$C$3)/365) -> 0 | K7: TFCs / Sukuks | L7: 0.4285 | M7: 1049894942 | N7: 0.1231 | O7: 839
A8: AM1 | B8: Alfalah Income Multiplier Fund | C8: =F8/$F$13 -> 0.2173913 | D8: 0.1075 | E8: 45 | F8: 500 | G8: =F8*(D8*(90/365)) -> 13.253425 | K8: Commercial Paper | L8: 0.0197 | M8: 48264706 | N8: 0.1183 | O8: 50
A9: AM1 | B9: NIT Income Fund | C9: =F9/$F$13 -> 0.34782609 | D9: 0.1094 | E9: 382 | F9: 800 | G9: =F9*(D9*($C$2-$C$3)/365) -> 21.580274 | K9: Cash | L9: 0.3601 | M9: 882362185 | N9: 0.112 | O9: 1
B10: MTB (6 Months) | C10: =F10/$F$13 -> 0 | D10: 0.1029 | E10: 180 | F10: 0 | G10: =F10*(D10*($C$2-$C$3)/365) -> 0 | I10: =I20/F20 -> 0 | J10: =H20/F20 -> 0.024152055 | K10: Other Assets | L10: 0.016 | M10: 39234284 | N10: 0
B11: MTB (9 Months) | C11: =F11/$F$13 -> 0.2173913 | D11: 0.1037 | E11: 270 | F11: 500 | G11: =F11*(D11*($C$2-$C$3)/365) -> 12.784932 | I11: =I10*365/180 -> 0 | J11: =J10*365/180 -> 0.048975 | L11: =SUM(L5:L10) -> 1 | M11: =SUM(M5:M10) -> 2450263617 | N11: 0.113 | O11: =SUM(O5:O10) -> 1468
B12: MTB (12 Months) | C12: =F12/$F$13 -> 0.2173913 | D12: 0.1035 | E12: 365 | F12: 500 | G12: =F12*(D12*($C$2-$C$3)/365) -> 12.760274
B13: Total | C13: =SUM(C7:C12) -> 1 | F13: =SUM(F7:F12) -> 2300 | G13: =SUM(G7:G12)+F171 -> 60.378904
J14: =H20/F20 -> 0.024152055 | K14: =B8 -> Alfalah Income Multiplier Fund
F15: =F8+F11+F12 -> 1500 | J15: =J14*365/180 -> 0.048975 | K15: Asset Allocation (% of Net Assets) | L15: 46042
B16: Avg return | D16: =(G13/F13)*365/($C$2-$C$3) -> 0.10646522 | K16: T-bills | L16: 0
B17: Benchmark (3MK-1%) | D17: =10.5%-1% -> 0.095 | K17: PIBs Fixed | L17: 0.0707
B18: Alpha | D18: =D16-D17 -> 0.011465217 | K18: TFCs/Sukuk/CPs | L18: 0.1633
G19: Gross Return | H19: 0.25 | K19: Ijarah | L19: 0.0099
B20: Daewoo Sukuk | D20: =10.56%+2.5% -> 0.1306 | E20: 180 | F20: 275 | G20: =F20*((D20/365)*90) -> 8.8557534 | H20: =G20-(G20*H19) -> 6.6418151 | K20: PIBs Flaoter | L20: 0.015
K21: Ready/Future | L21: 0.1889
D22: 0.1025 | E22: 180 | F22: 300 | G22: =F22*((D22/365)*E22) -> 15.164384 | J22: =G22*0.75 -> 11.373288 | K22: Clean Placements | L22: 0
D23: =D20-D22 -> 0.0281 | G23: =G20-G22 -> -6.3086301 | J23: =G22-J22 -> 3.7910959 | K23: MTS | L23: 0.1586
B24: Total | F24: =F20+F8+F9+F12+F11 -> 2575 | G24: =G20+G8+G9+G12+G11 -> 69.234658 | K24: Cash | L24: 0.3861
D25: Average Return | F25: =(G24/F24)*365/($C$2-$C$3) -> 0.10904272 | K25: Others | L25: 0.0075
D26: Alpha | F26: =F25-D17 -> 0.014042718
B28: Fund Allocation | C28: Rate | D28: Amount (PKR'Mn)
B29: Alfalah Income Multiplier Fund | C29: 0.1075 | D29: 500 | E29: =D29*C29*3/12 -> 13.4375
B30: 9 Months Treasury Bill | C30: =D11 -> 0.1037 | D30: =F11 -> 500 | E30: =D30*C30*3/12 -> 12.9625
B31: 12 Months Treasury Bill | C31: =D12 -> 0.1035 | D31: 500 | E31: =D31*C31*3/12 -> 12.9375

Sheet Dashboard
E10: * adjusted for WHT on debt instruments
E53: Returns on Banks, COIs, and Sukuks are net of WHT.

Sheet WoW Positions
B6: Instrument | C6: Cost of Placement | D6: Past Week | E6: Current Week | F6: Gain/Loss | G6: 1 Day Returns | H6: 15 Day Returns | I6: 30 Day Returns | J6: 90 Day Returns | K6: 7 Day NAV | L6: NAVs | M6: Number of Units | N6: Date of Placement | O6: Date of Maturity | P6: Weekly Yield | Q6: Rate | R6: Tax Adjusted Rate - 1 Day | S6: Gross Expectation | T6: Tax Adjusted Rate - 30 Day | U6: Days to Maturity | V6: Remaining Days | W6: Concentration (%) | X6: PVBP | Y6: Modified Duration | Z6: Convexity | AA6: Tenor | AB6: Secondary Yields | AC6: Dirty Pricing | AD6: Date
B7: MTBs (1Y) | C7: 1999988012 | D7: =C7*Q7/365*(IF(N7<$AD$7-7,($AD$7-N7-7),($AD$7-N7)))+C7 -> 2123393300 | E7: =C7*Q7/365*($AD$7-N7)+C7 -> 2127566425 | F7: =E7-D7 -> 4173125.7 | N7: 45895 | O7: 46240 | P7: =(E7-D7)/C7*365/7 -> 0.1088 | Q7: 0.1088 | R7: =S7 -> 0.1088 | S7: =P7 -> 0.1088 | T7: =S7 -> 0.1088 | U7: =O7-N7 -> 345 | V7: =O7-$AD$7 -> 131 | W7: =C7/$C$21 -> 0.2140575 | X7: =(V7/365)/(1+Q7)*E7*0.0001 -> 68866.552 | Y7: =(V7/365)/(1+Q7) -> 0.32368697 | Z7: =(V7/365)^2/(1+Q7)^2 -> 0.10477325 | AA7: 1Y | AB7: {=xlookup(AA7,'PKRV Rates'!$A$2:$A$21,'PKRV Rates'!$B$2:$B$21,0,1)/100} -> 0.1163 | AC7: =C7*(((1+(Q7*U7/365))/(1+(AB7*V7/365)))) -> 2117286781 | AD7: =today() -> 46109
B8: MTBs (6M) | C8: 474182500 | D8: =C8*Q8/365*(IF(N8<$AD$7-7,($AD$7-N8-7),($AD$7-N8)))+C8 -> 4.88369e+08 | E8: =C8*Q8/365*($AD$7-N8)+C8 -> 4.8936206e+08 | F8: =E8-D8 -> 993055.08 | N8: 46002 | O8: 46184 | P8: =(E8-D8)/C8*365/7 -> 0.1092 | Q8: 0.1092 | R8: =S8 -> 0.1092 | S8: =P8 -> 0.1092 | T8: =S8 -> 0.1092 | U8: =O8-N8 -> 182 | V8: =O8-$AD$7 -> 75 | W8: =C8/$C$21 -> 0.050751465 | X8: =(V8/365)/(1+Q8)*E8*0.0001 -> 9065.4388 | Y8: =(V8/365)/(1+Q8) -> 0.18525014 | Z8: =(V8/365)^2/(1+Q8)^2 -> 0.034317613 | AA8: 6M | AB8: {=xlookup(AA8,'PKRV Rates'!$A$2:$A$21,'PKRV Rates'!$B$2:$B$21,0,1)/100} -> 0.1136 | AC8: =C8*(((1+(Q8*U8/365))/(1+(AB8*V8/365)))) -> 4.8859688e+08 | AD8: =AD7 -> 46109
B9: MTBs (1Y) | C9: =1199982431+112795631 -> 1312778062 | D9: =C9*Q9/365*(IF(N9<$AD$7-7,($AD$7-N9-7),($AD$7-N9)))+C9 -> 1324161466 | E9: =C9*Q9/365*($AD$7-N9)+C9 -> 1326817594 | F9: =E9-D9 -> 2656127.7 | N9: 46072 | O9: =N9+364 -> 46436 | P9: =(E9-D9)/C9*365/7 -> 0.1055 | Q9: 0.1055 | R9: =S9 -> 0.1055 | S9: =P9 -> 0.1055 | T9: =S9 -> 0.1055 | U9: =O9-N9 -> 364 | V9: =O9-$AD$7 -> 327 | W9: =C9/$C$21 -> 0.14050584 | X9: =(V9/365)/(1+Q9)*E9*0.0001 -> 107524.48 | Y9: =(V9/365)/(1+Q9) -> 0.81039386 | Z9: =(V9/365)^2/(1+Q9)^2 -> 0.65673821 | AA9: 1Y | AB9: {=xlookup(AA9,'PKRV Rates'!$A$2:$A$21,'PKRV Rates'!$B$2:$B$21,0,1)/100} -> 0.1163 | AC9: =C9*(((1+(Q9*U9/365))/(1+(AB9*V9/365)))) -> 1313989441 | AD9: =AD8 -> 46109
B10: MTBs (1Y) | C10: 384022350 | D10: =C10*Q10/365*(IF(N10<$AD$7-7,($AD$7-N10-7),($AD$7-N10)))+C10 -> 3.8582357e+08 | E10: =C10*Q10/365*($AD$7-N10)+C10 -> 3.8661161e+08 | F10: =E10-D10 -> 788034.9 | N10: 46086 | O10: =N10+364 -> 46450 | P10: =(E10-D10)/C10*365/7 -> 0.107 | Q10: 0.107 | R10: =S10 -> 0.107 | S10: =P10 -> 0.107 | T10: =S10 -> 0.107 | U10: =O10-N10 -> 364 | V10: =O10-$AD$7 -> 341 | W10: =C10/$C$21 -> 0.041101679 | X10: =(V10/365)/(1+Q10)*E10*0.0001 -> 32627.874 | Y10: =(V10/365)/(1+Q10) -> 0.84394451 | Z10: =(V10/365)^2/(1+Q10)^2 -> 0.71224234 | AA10: 1Y | AB10: {=xlookup(AA10,'PKRV Rates'!$A$2:$A$21,'PKRV Rates'!$B$2:$B$21,0,1)/100} -> 0.1163 | AC10: =C10*(((1+(Q10*U10/365))/(1+(AB10*V10/365)))) -> 3.8334827e+08 | AD10: =AD9 -> 46109
B11: MTBs (1Y) | C11: 451587500 | D11: =C11*Q11/365*(IF(N11<$AD$7-7,($AD$7-N11-7),($AD$7-N11)))+C11 -> 4.5370959e+08 | E11: =C11*Q11/365*($AD$7-N11)+C11 -> 4.54638e+08 | F11: =E11-D11 -> 928414.41 | N11: 46086 | O11: =N11+364 -> 46450 | P11: =(E11-D11)/C11*365/7 -> 0.1072 | Q11: 0.1072 | R11: =S11 -> 0.1072 | S11: =P11 -> 0.1072 | T11: =S11 -> 0.1072 | U11: =O11-N11 -> 364 | V11: =O11-$AD$7 -> 341 | W11: =C11/$C$21 -> 0.048333136 | X11: =(V11/365)/(1+Q11)*E11*0.0001 -> 38361.994 | Y11: =(V11/365)/(1+Q11) -> 0.84379207 | Z11: =(V11/365)^2/(1+Q11)^2 -> 0.71198505 | AA11: 1Y | AB11: {=xlookup(AA11,'PKRV Rates'!$A$2:$A$21,'PKRV Rates'!$B$2:$B$21,0,1)/100} -> 0.1163 | AC11: =C11*(((1+(Q11*U11/365))/(1+(AB11*V11/365)))) -> 4.5087607e+08 | AD11: =AD10 -> 46109
B12: MTBs (1Y) | C12: 451709500 | D12: =C12*Q12/365*(IF(N12<$AD$7-7,($AD$7-N12-7),($AD$7-N12)))+C12 -> 4.538381e+08 | E12: =C12*Q12/365*($AD$7-N12)+C12 -> 4.5476937e+08 | F12: =E12-D12 -> 931264.11 | N12: 46086 | O12: =N12+364 -> 46450 | P12: =(E12-D12)/C12*365/7 -> 0.1075 | Q12: =10.75% -> 0.1075 | R12: =S12 -> 0.1075 | S12: =P12 -> 0.1075 | T12: =S12 -> 0.1075 | U12: =O12-N12 -> 364 | V12: =O12-$AD$7 -> 341 | W12: =C12/$C$21 -> 0.048346194 | X12: =(V12/365)/(1+Q12)*E12*0.0001 -> 38362.684 | Y12: =(V12/365)/(1+Q12) -> 0.8435635 | Z12: =(V12/365)^2/(1+Q12)^2 -> 0.71159938 | AA12: 1Y | AB12: {=xlookup(AA12,'PKRV Rates'!$A$2:$A$21,'PKRV Rates'!$B$2:$B$21,0,1)/100} -> 0.1163 | AC12: =C12*(((1+(Q12*U12/365))/(1+(AB12*V12/365)))) -> 4.5111977e+08 | AD12: =AD11 -> 46109
B13: Faysal Bank | C13: 229894920 | D13: =C13 -> 229894920 | E13: =D13 -> 229894920 | F13: =D13*Q13*7/365*(1-20%) -> 361533.38 | P13: =F13/D13*365/7 -> 0.082 | Q13: 0.1025 | R13: =S13 -> 0.082 | S13: =Q13*0.8 -> 0.082 | T13: =S13 -> 0.082 | U13: 1 | V13: 1 | W13: =C13/$C$21 -> 0.024605514 | X13: =(V13/365)/(1+Q13)*E13*0.0001 -> 57.12917 | Y13: =(V13/365)/(1+Q13) -> 0.0024850123 | Z13: =(V13/365)^2/(1+Q13)^2 -> 6.175286e-06 | AC13: =E13 -> 229894920 | AD13: =AD12 -> 46109
B14: Samba Bank | C14: 0 | D14: =C14 -> 0 | E14: =D14 -> 0 | F14: =D14*Q14*7/365*(1-20%) -> 0 | O14: 46118 | P14: =Q14*(1-0.2) -> 0.082 | Q14: 0.1025 | R14: =S14 -> 0.082 | S14: =Q14*0.8 -> 0.082 | T14: =S14 -> 0.082 | U14: =V14 -> 9 | V14: =O14-AD7 -> 9 | W14: =C14/$C$21 -> 0 | X14: =(V14/365)/(1+Q14)*E14*0.0001 -> 0 | Y14: =(V14/365)/(1+Q14) -> 0.02236511 | Z14: =(V14/365)^2/(1+Q14)^2 -> 0.00050019816 | AC14: =E14 -> 0 | AD14: =AD13 -> 46109
B15: COI | C15: 1300000000 | D15: =(C15*Q15/365*(IF(N15<$AD$7-7,($AD$7-N15-7),($AD$7-N15)))*(1-20%))+C15 -> 1305727123 | E15: =(C15*Q15/365*($AD$7-N15)*(1-20%))+C15 -> 1307731616 | F15: =E15-D15 -> 2004493.2 | N15: 46082 | O15: 46112 | P15: =(E15-D15)/C15*365/7 -> 0.0804 | Q15: 0.1005 | R15: =S15 -> 0.0804 | S15: =Q15*0.8 -> 0.0804 | T15: =S15 -> 0.0804 | U15: 30 | V15: =O15-AD7 -> 3 | W15: =C15/$C$21 -> 0.13913821 | X15: =(V15/365)/(1+Q15)*E15*0.0001 -> 976.69051 | Y15: =(V15/365)/(1+Q15) -> 0.0074685853 | Z15: =(V15/365)^2/(1+Q15)^2 -> 5.5779766e-05 | AC15: =E15 -> 1307731616 | AD15: =AD14 -> 46109
B16: Alfalah Government Securities Fund Plan II | C16: 827608440 | D16: =M16*K16 -> 8.3479721e+08 | E16: =L16*M16 -> 8.3542376e+08 | F16: =E16-D16 -> 626551.65 | G16: {=xlookup($B16,'MUFAP Data'!$C:$C,'MUFAP Data'!H:H,0,0)/100} -> 0.0781 | H16: {=xlookup($B16,'MUFAP Data'!$C:$C,'MUFAP Data'!I:I,0,0)/100} -> -0.0193 | I16: {=xlookup($B16,'MUFAP Data'!$C:$C,'MUFAP Data'!J:J,0,0)/100} -> -0.2778 | J16: {=xlookup($B16,'MUFAP Data'!$C:$C,'MUFAP Data'!K:K,0,0)/100} -> 0.023 | K16: 105.79 | L16: {=xlookup($B16,'MUFAP Data'!$C:$C,'MUFAP Data'!G:G,0,0)} -> 105.8694 | M16: 7891078.7 | P16: =(L16/K16-1)*365/7 -> 0.039135484 | Q16: 0.07 | R16: =G16 -> 0.0781 | S16: =Q16 -> 0.07 | T16: =I16 -> -0.2778 | U16: =0.78*365 -> 284.7 | V16: =1*U16 -> 284.7 | W16: =C16/$C$21 -> 0.088578429 | X16: =(V16/365)/(1+Q16)*E16*0.0001 -> 60900.05 | Y16: =(V16/365)/(1+Q16) -> 0.72897196 | Z16: =(V16/365)^2/(1+Q16)^2 -> 0.53140012 | AC16: =E16 -> 8.3542376e+08 | AD16: =AD15 -> 46109
B17: Alfalah MTS Fund | C17: =D17 -> 3.1337318e+08 | D17: =M17*K17 -> 3.1337318e+08 | E17: =L17*M17 -> 3.1407429e+08 | F17: =E17-D17 -> 701109.89 | G17: {=xlookup($B17,'MUFAP Data'!$C:$C,'MUFAP Data'!H:H,0,0)/100} -> 0.1124 | H17: {=xlookup($B17,'MUFAP Data'!$C:$C,'MUFAP Data'!I:I,0,0)/100} -> 0.0949 | I17: {=xlookup($B17,'MUFAP Data'!$C:$C,'MUFAP Data'!J:J,0,0)/100} -> 0.0876 | J17: {=xlookup($B17,'MUFAP Data'!$C:$C,'MUFAP Data'!K:K,0,0)/100} -> 0.0945 | K17: 112.01 | L17: {=xlookup($B17,'MUFAP Data'!$C:$C,'MUFAP Data'!G:G,0,0)} -> 112.2606 | M17: 2797725 | P17: =(L17/K17-1)*365/7 -> 0.11665923 | Q17: 0.07 | R17: =G17 -> 0.1124 | S17: =Q17 -> 0.07 | T17: =I17 -> 0.0876 | U17: 1 | V17: =1*U17 -> 1 | W17: =C17/$C$21 -> 0.033540141 | X17: =(V17/365)/(1+Q17)*E17*0.0001 -> 80.418458 | Y17: =(V17/365)/(1+Q17) -> 0.0025604916 | Z17: =(V17/365)^2/(1+Q17)^2 -> 6.5561173e-06 | AC17: =E17 -> 3.1407429e+08 | AD17: =AD16 -> 46109
B18: Alfalah GHP Income Multiplier Fund | C18: =D18 -> 5.029355e+08 | D18: =M18*K18 -> 5.029355e+08 | E18: =L18*M18 -> 5.0359115e+08 | F18: =E18-D18 -> 655651.33 | G18: {=xlookup($B18,'MUFAP Data'!$C:$C,'MUFAP Data'!H:H,0,0)/100} -> 0.1912 | H18: {=xlookup($B18,'MUFAP Data'!$C:$C,'MUFAP Data'!I:I,0,0)/100} -> 0.0561 | I18: {=xlookup($B18,'MUFAP Data'!$C:$C,'MUFAP Data'!J:J,0,0)/100} -> 0.0854 | J18: {=xlookup($B18,'MUFAP Data'!$C:$C,'MUFAP Data'!K:K,0,0)/100} -> 0.0626 | K18: 62.21 | L18: {=xlookup($B18,'MUFAP Data'!$C:$C,'MUFAP Data'!G:G,0,0)} -> 62.2911 | M18: 8084480 | P18: =(L18/K18-1)*365/7 -> 0.06797598 | Q18: 0.07 | R18: =G18 -> 0.1912 | S18: =Q18 -> 0.07 | T18: =I18 -> 0.0854 | U18: =0.22*365 -> 80.3 | V18: =1*U18 -> 80.3 | W18: =C18/$C$21 -> 0.053828881 | X18: =(V18/365)/(1+Q18)*E18*0.0001 -> 10354.211 | Y18: =(V18/365)/(1+Q18) -> 0.20560748 | Z18: =(V18/365)^2/(1+Q18)^2 -> 0.042274434 | AC18: =E18 -> 5.0359115e+08 | AD18: =AD17 -> 46109
B19: MCB Investment Savings Plan I | C19: =D19 -> 8.2014783e+08 | D19: =M19*K19 -> 8.2014783e+08 | E19: =L19*M19 -> 8.2213926e+08 | F19: =E19-D19 -> 1991432.5 | G19: {=xlookup($B19,'MUFAP Data'!$C:$C,'MUFAP Data'!H:H,0,0)/100} -> 0.1201 | H19: {=xlookup($B19,'MUFAP Data'!$C:$C,'MUFAP Data'!I:I,0,0)/100} -> 0.0999 | I19: {=xlookup($B19,'MUFAP Data'!$C:$C,'MUFAP Data'!J:J,0,0)/100} -> 0.0931 | J19: {=xlookup($B19,'MUFAP Data'!$C:$C,'MUFAP Data'!K:K,0,0)/100} -> 0.0992 | K19: 108.89 | L19: {=xlookup($B19,'MUFAP Data'!$C:$C,'MUFAP Data'!G:G,0,0)} -> 109.1544 | M19: 7531893 | P19: =(L19/K19-1)*365/7 -> 0.12661008 | Q19: 0.07 | R19: =G19 -> 0.1201 | S19: =Q19 -> 0.07 | T19: =I19 -> 0.0931 | U19: 1 | V19: =1*U19 -> 1 | W19: =C19/$C$21 -> 0.087779924 | X19: =(V19/365)/(1+Q19)*E19*0.0001 -> 210.50807 | Y19: =(V19/365)/(1+Q19) -> 0.0025604916 | Z19: =(V19/365)^2/(1+Q19)^2 -> 6.5561173e-06 | AC19: =E19 -> 8.2213926e+08 | AD19: =AD18 -> 46109
B20: Daewoo Short Term SUKUK | C20: 275000000 | D20: =(C20*Q20/365*(IF(N20<$AD$7-7,($AD$7-N20-7),($AD$7-N20)))*(1-25%))+C20 -> 2.7677522e+08 | E20: =(C20*Q20*($AD$7-N20)/365*(1-20%))+C20 -> 2.7744586e+08 | F20: =E20-D20 -> 670638.36 | N20: 46078 | O20: =N20+180 -> 46258 | P20: =(E20-D20)/C20*365/7 -> 0.12716 | Q20: 0.1309 | R20: =S20 -> 0.12716 | S20: =P20 -> 0.12716 | T20: =S20 -> 0.12716 | U20: =O20-N20 -> 180 | V20: =O20-$AD$7 -> 149 | W20: =C20/$C$21 -> 0.029433083 | X20: =(V20/365)/(1+Q20)*E20*0.0001 -> 10014.919 | Y20: =(V20/365)/(1+Q20) -> 0.36096841 | Z20: =(V20/365)^2/(1+Q20)^2 -> 0.1302982 | AC20: =E20 -> 2.7744586e+08 | AD20: =AD19 -> 46109
B21: Total | C21: =SUM(C7:C20) -> 9343227791 | D21: =SUM(D7:D20) -> 9512946015 | E21: =SUM(E7:E20) -> 9530065914 | F21: =SUM(F7:F20) -> 17481432 | P21: =sumproduct(P7:P20,W7:W20) -> 0.097530586 | Q21: =sumproduct(Q7:Q20,$W$7:$W$20) -> 0.097250452 | R21: =sumproduct(R7:R20,$W$7:$W$20) -> 0.1069007 | S21: =sumproduct(S7:S20,$W$7:$W$20) -> 0.093839281 | T21: =sumproduct(T7:T20,$W$7:$W$20) -> 0.066478691 | U21: =sumproduct(U7:U20,W7:W20) -> 223.54178 | V21: =sumproduct(V7:V20,W7:W20) -> 159.26623 | W21: =SUM(W7:W20) -> 1 | X21: =SUM(X7:X20) -> 377402.95 | Y21: =sumproduct(Y7:Y20,$W$7:$W$20) -> 0.39648232 | Z21: =sumproduct(Z7:Z20,$W$7:$W$20) -> 0.26772463 | AC21: =SUM(AC7:AC20) -> 9495518070
B22: Liabilities
B23: Borrowing | C23: 1238000000 | D23: =C23 -> 1238000000 | E23: =D23 -> 1238000000 | F23: =E23*7/365*Q23 -> -2511952.9 | N23: =N15 -> 46082 | O23: =O15 -> 46112 | Q23: -0.1058 | AC23: =C23 -> 1238000000
F24: =F21+F23 -> 14969479 | P24: =(F21+F23)/(C21-C23)*365/7 -> 0.096302218
F25: =F23/7*90 -> -32296537
B26: NAV | D26: =(D21-D23)/D27 -> 82.74946 | E26: =(E21-E23)/E27 -> 82.920659 | AC26: =(AC21-AC23)/AC27 -> 82.575181
B27: NAV Units | D27: =10^8 -> 100000000 | E27: =10^8 -> 100000000 | AC27: =10^8 -> 100000000
E28: =E26/D26-1 -> 0.0020688834 | AC28: =AC26/E26-1 -> -0.0041663736
B31: Benchmark | C31: =C34-1% -> 0.1038
B32: Alpha | C32: =T21-C31 -> -0.037321309
B34: 3MK | C34: =IFERROR(__xludf.DUMMYFUNCTION("ai(""Write today's 3 month KIBOR in the active cell"",C36)"),"11.38%") -> 11.38%

Sheet Monthly Stakeholder Update
A2: Mutual Funds | B2: Begining Nav | C2: Latest Nav | D2: Units | E2: Begining Value | F2: Latest Value | G2: Monthly Return | H2: Mufap 30 day returns
A3: Alfalah Government Securities Fund Plan II | B3: 105.97 | C3: 105.95 | D3: ='WoW Positions'!M16 -> 7891078.7 | E3: =B3*D3 -> 8.3621761e+08 | F3: =C3*D3 -> 8.3605979e+08 | G3: =(F3/E3-1)*365/30 -> -0.0022962474 | H3: 0.002
A4: Alfalah MTS Fund | B4: 111.41 | C4: 112.23 | D4: ='WoW Positions'!M17 -> 2797725 | E4: =B4*D4 -> 3.1169454e+08 | F4: =C4*D4 -> 3.1398868e+08 | G4: =(F4/E4-1)*365/30 -> 0.089549113 | H4: 0.0968
A5: Alfalah GHP Income Multiplier Fund | B5: 62.07 | C5: 62.28 | D5: ='WoW Positions'!M18 -> 8084480 | E5: =B5*D5 -> 5.0180367e+08 | F5: =C5*D5 -> 5.0350141e+08 | G5: =(F5/E5-1)*365/30 -> 0.041163203 | H5: 0.042
A6: MCB Investment Savings Plan I | B6: 108.3 | C6: 109.13 | D6: ='WoW Positions'!M19 -> 7531893 | E6: =B6*D6 -> 8.1570401e+08 | F6: =C6*D6 -> 8.2195548e+08 | G6: =(F6/E6-1)*365/30 -> 0.093244075 | H6: 0.1
A7: MTBs | B7: Cost | C7: Yield | D7: Days to Maturity | E7: Remaining days | F7: Days Elapsed | G7: Accrued Interest | H7: Total Value
A8: MTBs (1Y) | B8: ='WoW Positions'!C7 -> 1999988012 | C8: ='WoW Positions'!Q7 -> 0.1088 | D8: ='WoW Positions'!U7 -> 345 | E8: ='WoW Positions'!V7 -> 131 | F8: =D8-E8 -> 214 | G8: =B8*C8*F8/365 -> 1.2757841e+08 | H8: =B8+G8 -> 2127566425
A9: MTBs (6M) | B9: ='WoW Positions'!C8 -> 474182500 | C9: ='WoW Positions'!Q8 -> 0.1092 | D9: ='WoW Positions'!U8 -> 182 | E9: ='WoW Positions'!V8 -> 75 | F9: =D9-E9 -> 107 | G9: =B9*C9*F9/365 -> 15179556 | H9: =B9+G9 -> 4.8936206e+08
A10: MTBs (1Y) | B10: ='WoW Positions'!C9 -> 1312778062 | C10: ='WoW Positions'!Q9 -> 0.1055 | D10: ='WoW Positions'!U9 -> 364 | E10: ='WoW Positions'!V9 -> 327 | F10: =D10-E10 -> 37 | G10: =B10*C10*F10/365 -> 14039532 | H10: =B10+G10 -> 1326817594
A11: MTBs (1Y) | B11: ='WoW Positions'!C10 -> 384022350 | C11: ='WoW Positions'!Q10 -> 0.107 | D11: ='WoW Positions'!U10 -> 364 | E11: ='WoW Positions'!V10 -> 341 | F11: =D11-E11 -> 23 | G11: =B11*C11*F11/365 -> 2589257.5 | H11: =B11+G11 -> 3.8661161e+08
A12: MTBs (1Y) | B12: ='WoW Positions'!C11 -> 451587500 | C12: ='WoW Positions'!Q11 -> 0.1072 | D12: ='WoW Positions'!U11 -> 364 | E12: ='WoW Positions'!V11 -> 341 | F12: =D12-E12 -> 23 | G12: =B12*C12*F12/365 -> 3050504.5 | H12: =B12+G12 -> 4.54638e+08
A13: MTBs (1Y) | B13: ='WoW Positions'!C12 -> 451709500 | C13: ='WoW Positions'!Q12 -> 0.1075 | D13: ='WoW Positions'!U12 -> 364 | E13: ='WoW Positions'!V12 -> 341 | F13: =D13-E13 -> 23 | G13: =B13*C13*F13/365 -> 3059867.8 | H13: =B13+G13 -> 4.5476937e+08
A14: COI | B14: Principal | C14: Rate | D14: Days | E14: End Value | F14: Accrued Interest
B15: 1300000000 | C15: 0.1005 | D15: 30 | E15: =B15+(B15*C15*D15/365) -> 1310738356 | F15: =E15-B15 -> 10738356
A16: Bank Placements

Sheet WoW Archive
B2: No calculations - just values to be pasted here on a WoW basis.
B4: Instrument | C4: Cost of Placement | D4: Past Week | E4: Current Week | F4: Gain/Loss | G4: 1 Day Returns | H4: 15 Day Returns | I4: 30 Day Returns | J4: 90 Day Returns | K4: 7 Day NAV | L4: NAVs | M4: Number of Units | N4: Date of Placement | O4: Date of Maturity | P4: Weekly Yield | Q4: Rate | R4: Tax Adjusted Rate | S4: Days to Maturity | T4: Remaining Days | U4: Concentration (%) | V4: PVBP | W4: Modified Duration | X4: Convexity | Y4: Date
B5: MTBs (1Y) | C5: 1999988012 | D5: 2.1204125e+09 | E5: 2.1245856e+09 | F5: 4173125.7 | N5: 45895 | O5: 46240 | P5: 0.1088 | Q5: 0.1088 | R5: 0.1088 | S5: 345 | T5: 136 | U5: 0.21354359 | V5: 71394.879 | W5: 0.33604143 | X5: 0.11292384 | Y5: 46104
B6: MTBs (6M) | C6: 474182500 | D6: 4.8765968e+08 | E6: 4.8865273e+08 | F6: 993055.08 | N6: 46002 | O6: 46184 | P6: 0.1092 | Q6: 0.1092 | R6: 0.1092 | S6: 182 | T6: 80 | U6: 0.05062962 | V6: 9655.7851 | W6: 0.19760015 | X6: 0.039045818 | Y6: 46104
B7: MTBs (1Y) | C7: 1312778062 | D7: 1.3222642e+09 | E7: 1.3249204e+09 | F7: 2656127.7 | N7: 46072 | O7: 46436 | P7: 0.1055 | Q7: 0.1055 | R7: 0.1055 | S7: 364 | T7: 332 | U7: 0.14016851 | V7: 109012.49 | W7: 0.8227852 | X7: 0.67697549 | Y7: 46104
B8: MTBs (1Y) | C8: 384022350 | D8: 3.8526069e+08 | E8: 3.8604873e+08 | F8: 788034.9 | N8: 46086 | O8: 46450 | P8: 0.107 | Q8: 0.107 | R8: 0.107 | S8: 364 | T8: 346 | U8: 0.041003001 | V8: 33058.088 | W8: 0.85631907 | X8: 0.73328234 | Y8: 46104
B9: MTBs (1Y) | C9: 451587500 | D9: 4.5304644e+08 | E9: 4.5397485e+08 | F9: 928414.41 | N9: 46086 | O9: 46450 | P9: 0.1072 | Q9: 0.1072 | R9: 0.1072 | S9: 364 | T9: 346 | U9: 0.048217096 | V9: 38867.71 | W9: 0.85616438 | X9: 0.73301745 | Y9: 46104
B10: MTBs (1Y) | C10: 451709500 | D10: 4.5317292e+08 | E10: 4.5410418e+08 | F10: 931264.11 | N10: 46086 | O10: 46450 | P10: 0.1075 | Q10: 0.1075 | R10: 0.1075 | S10: 364 | T10: 346 | U10: 0.048230123 | V10: 38868.251 | W10: 0.85593247 | X10: 0.73262039 | Y10: 46104
B11: Faysal Bank | C11: 253133899 | D11: 253133899 | E11: 253133899 | F11: 398079.06 | P11: 0.082 | Q11: 0.1025 | R11: 0.082 | S11: 1 | T11: 1 | U11: 0.027027722 | V11: 62.904084 | W11: 0.0024850123 | X11: 6.175286e-06 | Y11: 46104
B12: Samba Bank | C12: 0 | D12: 0 | E12: 0 | F12: 0 | O12: 46118 | P12: 0 | Q12: 0.105 | R12: 0.084 | S12: 14 | T12: 14 | U12: 0 | V12: 0 | W12: 0.034711461 | X12: 0.0012048855 | Y12: 46104
B13: COI | C13: 1300000000 | D13: 1.3042953e+09 | E13: 1.3062998e+09 | F13: 2004493.2 | N13: 46082 | O13: 46112 | P13: 0.0804 | Q13: 0.1005 | R13: 0.0804 | S13: 30 | T13: 8 | U13: 0.13880416 | V13: 2601.6565 | W13: 0.019916227 | X13: 0.00039665611 | Y13: 46104
B14: Alfalah Government Securities Fund Plan II | C14: 827608440 | D14: 8.3448157e+08 | E14: 8.3493452e+08 | F14: 452947.92 | G14: 0.0796 | H14: -0.0387 | I14: 0.0679 | J14: -0.0648 | K14: 105.75 | L14: 105.8074 | M14: 7891078.7 | P14: 0.0283026 | Q14: 0.03 | R14: 0.03 | S14: 284.7 | T14: 284.7 | U14: 0.088365767 | V14: 63228.051 | W14: 0.75728155 | X14: 0.57347535 | Y14: 46104
B15: Alfalah MTS Fund | C15: 313233291 | D15: 313233291 | E15: 3.1344396e+08 | F15: 210668.69 | G15: 0.1128 | H15: 0.096 | I15: 0.0923 | J15: 0.095 | K15: 111.96 | L15: 112.0353 | M15: 2797725 | P15: 0.035069285 | Q15: 0.03 | R15: 0.03 | S15: 1 | T15: 1 | U15: 0.033444681 | V15: 83.373842 | W15: 0.0026599282 | X15: 7.0752179e-06 | Y15: 46104
B16: Alfalah GHP Income Multiplier Fund | C16: 5.0277381e+08 | D16: 5.0277381e+08 | E16: 5.0303332e+08 | F16: 259511.81 | G16: 0.1953 | H16: 0.0584 | I16: 0.0599 | J16: 0.0552 | K16: 62.19 | L16: 62.2221 | M16: 8084480 | P16: 0.026914065 | Q16: 0.05 | R16: 0.05 | S16: 80.3 | T16: 80.3 | U16: 0.053682383 | V16: 10539.746 | W16: 0.20952381 | X16: 0.043900227 | Y16: 46104
B17: MCB Investment Savings Plan I | C17: 8.1969592e+08 | D17: 8.1969592e+08 | E17: 8.2034592e+08 | F17: 650002.37 | G17: 0.1204 | H17: 0.0998 | I17: 0.0996 | J17: 0.0997 | K17: 108.83 | L17: 108.9163 | M17: 7531893 | P17: 0.041348236 | Q17: 0.05 | R17: 0.05 | S17: 1 | T17: 1 | U17: 0.087520928 | V17: 214.04982 | W17: 0.0026092629 | X17: 6.8082528e-06 | Y17: 46104
B18: Daewoo Short Term SUKUK | C18: 275000000 | D18: 2.7640538e+08 | E18: 2.7705136e+08 | F18: 645982.53 | N18: 46078 | O18: 46258 | P18: 0.122485 | Q18: 0.1309 | R18: 0.1309 | S18: 180 | T18: 154 | U18: 0.029362419 | V18: 10336.272 | W18: 0.37308145 | X18: 0.13918977 | Y18: 46104
B19: Total | C19: 9.3657133e+09 | D19: 9.5258357e+09 | E19: 9.5405293e+09 | F19: 15091707 | P19: 0.0840011 | Q19: 0.089569186 | R19: 0.086225154 | S19: 223.00613 | T19: 162.43469 | U19: 1 | V19: 387923.25 | W19: 0.40703665 | X19: 0.27890207
B20: Liabilities
B21: Borrowing | C21: 1238000000 | D21: 1238000000 | E21: 1238000000 | F21: -2511952.9 | N21: 46082 | O21: 46112 | Q21: -0.1058 | T21: 90
F22: 12579754 | P22: 0.080704661
F23: -32296537
B24: NAV | D24: 82.878357 | E24: 83.025293
B25: NAV Units | D25: 100000000 | E25: 100000000
E26: 0.001772915

Sheet Pivot Table 1

Sheet Daewoo Sukuk
B4: National Credit Guarantee Company Limited
B5: Investments Team | G5: Date: | H5: =TODAY() -> 46109
B7: Proposed Transaction
B8: Placement in Sukuk
B9: Bank/Company/SPV | C9: Amount (PKR'Mn) | D9: Rate | E9: Days | F9: Gross (PKR'Mn) | G9: Tax @ 25% | H9: Net (PKR'Mn)
B10: Daewoo Pakistan Express Bus Service Limited | C10: 275 | D10: =10.56%+2.5% -> 0.1306 | E10: 180 | F10: =C10*(D10*E10/C23) -> 17.711507 | G10: =F10*25% -> 4.4278767 | H10: =F10-G10 -> 13.28363
F11: =F10/C10 -> 0.064405479 | H11: =H10/C10 -> 0.04830411
B12: Annualized Yield | F12: =F11*(365/180) -> 0.1306 | H12: =H11*(365/180) -> 0.09795
B14: Status Quo
B15: Bank/Company/SPV | C15: Amount (PKR'Mn) | D15: Rate | E15: Days | F15: Gross (PKR'Mn) | G15: Tax @ 20% | H15: Net (PKR'Mn)
B16: Faysal Bank Limited | C16: 275 | D16: 0.1025 | E16: 180 | F16: =C16*(D16*E16/C23) -> 13.900685 | G16: =F16*20% -> 2.780137 | H16: =F16-G16 -> 11.120548
F17: =F16/C16 -> 0.050547945 | H17: =H16/C16 -> 0.040438356
B18: Annualized Yield | F18: =F17*(365/180) -> 0.1025 | H18: =H17*(365/180) -> 0.082
B20: Delta (Gross) | C20: =F12-F18 -> 0.0281
B21: Delta (Net) | C21: =H12-H18 -> 0.01595
B23: Period (days) | C23: 365

Sheet IOM-007
B5: National Credit Guarantee Company Limited
B6: Investments Team | G6: Date: | H6: =TODAY() -> 46109
B8: Proposed Transaction
B9: Govt. Security Placement
C10: Placement | D10: Rate | E10: Days | F10: Gross | G10: Tax | H10: Net
B11: 12M MTBs | C11: 1238 | D11: 0.1055 | E11: 90 | F11: =C11*(D11*E11/C24) -> 32.204959 | G11: =F11*15% -> 4.8307438 | H11: =F11-G11 -> 27.374215
F12: =F11/C11 -> 0.026013699 | H12: =H11/C11 -> 0.022111644
B13: Annualized Yield | H13: =H12*(365/E11) -> 0.089675
B15: Status Quo
C16: Placement | D16: Rate | E16: Days | F16: Gross | G16: Tax | H16: Net
B17: Faysal Bank Limited | C17: =C11 -> 1238 | D17: 0.1025 | E17: 90 | F17: =C17*(D17*E17/C24) -> 31.289178 | G17: =F17*20% -> 6.2578356 | H17: =F17-G17 -> 25.031342
F18: =F17/C17 -> 0.025273973 | H18: =H17/C17 -> 0.020219178
B19: Annualized Yield | H19: =H18*(365/E17) -> 0.082
B21: Delta (Gross) | C21: =D11-D17 -> 0.003
B22: Delta (Net) | C22: =H13-H19 -> 0.007675
B24: Period (days) | C24: 365
B25: Note: All amounts mentioned in PKR mn unless stated otherwise.

Sheet IOM-008
B4: National Credit Guarantee Company Limited
B5: Investments Team | G5: Date: | H5: =TODAY() -> 46109
B7: Proposed Transaction
B8: Reverse Repo
C9: Placement | D9: Rate | E9: Days | F9: Gross | G9: Tax | H9: Net
B10: Pak Oman Investment Company | C10: 1000 | D10: 0.105 | E10: 30 | F10: =C10*(D10*E10/C23) -> 8.630137 | G10: =F10*20% -> 1.7260274 | H10: =F10-G10 -> 6.9041096
F11: =F10/C10 -> 0.008630137 | H11: =H10/C10 -> 0.0069041096
B12: Annualized Yield | H12: =H11*(365/E10) -> 0.084
B14: Status Quo
C15: Placement | D15: Rate | E15: Days | F15: Gross | G15: Tax | H15: Net
B16: Faysal Bank Limited | C16: 1000 | D16: 0.1025 | E16: 30 | F16: =C16*(D16*E16/C23) -> 8.4246575 | G16: =F16*20% -> 1.6849315 | H16: =F16-G16 -> 6.739726
F17: =F16/C16 -> 0.0084246575 | H17: =H16/C16 -> 0.006739726
B18: Annualized Yield | H18: =H17*(365/E16) -> 0.082
B20: Delta (Gross) | C20: =D10-D16 -> 0.0025
B21: Delta (Net) | C21: =H12-H18 -> 0.002
B23: Period (days) | C23: 365
B24: Note: All amounts mentioned in PKR mn unless stated otherwise.
B52: National Credit Guarantee Company Limited
B53: Investments Team | G53: Date: | H53: =TODAY() -> 46109
B55: Proposed Transaction
B56: Govt. Security Placement
C57: Placement | D57: Rate | E57: Days | F57: Gross | G57: Tax | H57: Net
B58: 12M MTBs | C58: 1238 | D58: 0.1055 | E58: 90 | F58: =C58*(D58*E58/C71) -> 32.204959 | G58: =F58*15% -> 4.8307438 | H58: =F58-G58 -> 27.374215
F59: =F58/C58 -> 0.026013699 | H59: =H58/C58 -> 0.022111644
B60: Annualized Yield | H60: =H59*(365/E58) -> 0.089675
B62: Status Quo
C63: Placement | D63: Rate | E63: Days | F63: Gross | G63: Tax | H63: Net
B64: Faysal Bank Limited | C64: =C58 -> 1238 | D64: 0.1025 | E64: 90 | F64: =C64*(D64*E64/C71) -> 31.289178 | G64: =F64*20% -> 6.2578356 | H64: =F64-G64 -> 25.031342
F65: =F64/C64 -> 0.025273973 | H65: =H64/C64 -> 0.020219178
B66: Annualized Yield | H66: =H65*(365/E64) -> 0.082
B68: Delta (Gross) | C68: =D58-D64 -> 0.003
B69: Delta (Net) | C69: =H60-H66 -> 0.007675
B71: Period (days) | C71: 365
B72: Note: All amounts mentioned in PKR mn unless stated otherwise.

Sheet IOM-009
B4: National Credit Guarantee Company Limited
B5: Investments Team | G5: Date: | H5: =TODAY() -> 46109
B7: Proposed Transaction
B8: Reverse Repo
C9: Placement | D9: Rate | E9: Days | F9: Gross | G9: Tax | H9: Net
B10: Pak Oman Investment Company | C10: 1000 | D10: 0.105 | E10: 30 | F10: =C10*(D10*E10/C23) -> 8.630137 | G10: =F10*20% -> 1.7260274 | H10: =F10-G10 -> 6.9041096
F11: =F10/C10 -> 0.008630137 | H11: =H10/C10 -> 0.0069041096
B12: Annualized Yield | H12: =H11*(365/E10) -> 0.084
B14: Status Quo
C15: Placement | D15: Rate | E15: Days | F15: Gross | G15: Tax | H15: Net
B16: Faysal Bank Limited | C16: 1000 | D16: 0.1025 | E16: 30 | F16: =C16*(D16*E16/C23) -> 8.4246575 | G16: =F16*20% -> 1.6849315 | H16: =F16-G16 -> 6.739726
F17: =F16/C16 -> 0.0084246575 | H17: =H16/C16 -> 0.006739726
B18: Annualized Yield | H18: =H17*(365/E16) -> 0.082
B20: Delta (Gross) | C20: =D10-D16 -> 0.0025
B21: Delta (Net) | C21: =H12-H18 -> 0.002
B23: Period (days) | C23: 365
B24: Note: All amounts mentioned in PKR mn unless stated otherwise.
B52: National Credit Guarantee Company Limited
B53: Investments Team | G53: Date: | H53: =TODAY() -> 46109
B55: Proposed Transaction
B56: Govt. Security Placement
C57: Placement | D57: Rate | E57: Days | F57: Gross | G57: Tax | H57: Net
B58: 6M MTBs | C58: 500 | D58: 0.105 | E58: 180 | F58: =C58*(D58*E58/C71) -> 25.890411 | G58: =F58*15% -> 3.8835616 | H58: =F58-G58 -> 22.006849
F59: =F58/C58 -> 0.051780822 | H59: =H58/C58 -> 0.044013699
B60: Annualized Yield | H60: =H59*(365/E58) -> 0.08925
B62: Status Quo
C63: Placement | D63: Rate | E63: Days | F63: Gross | G63: Tax | H63: Net
B64: Faysal Bank Limited | C64: =C58 -> 500 | D64: 0.1025 | E64: 180 | F64: =C64*(D64*E64/C71) -> 25.273973 | G64: =F64*20% -> 5.0547945 | H64: =F64-G64 -> 20.219178
F65: =F64/C64 -> 0.050547945 | H65: =H64/C64 -> 0.040438356
B66: Annualized Yield | H66: =H65*(365/E64) -> 0.082
B68: Delta (Gross) | C68: =D58-D64 -> 0.0025
B69: Delta (Net) | C69: =H60-H66 -> 0.00725
B71: Period (days) | C71: 365
B72: Note: All amounts mentioned in PKR mn unless stated otherwise.

Sheet IOM-010
B4: National Credit Guarantee Company Limited
B5: Investments Team | G5: Date: | H5: =TODAY() -> 46109
B7: Proposed Transaction
B8: Reverse Repo
C9: Placement | D9: Rate | E9: Days | F9: Gross | G9: Tax | H9: Net
B10: Pak Oman Investment Company | C10: 1000 | D10: 0.105 | E10: 30 | F10: =C10*(D10*E10/C23) -> 8.630137 | G10: =F10*20% -> 1.7260274 | H10: =F10-G10 -> 6.9041096
F11: =F10/C10 -> 0.008630137 | H11: =H10/C10 -> 0.0069041096
B12: Annualized Yield | H12: =H11*(365/E10) -> 0.084
B14: Status Quo
C15: Placement | D15: Rate | E15: Days | F15: Gross | G15: Tax | H15: Net
B16: Faysal Bank Limited | C16: 1000 | D16: 0.1025 | E16: 30 | F16: =C16*(D16*E16/C23) -> 8.4246575 | G16: =F16*20% -> 1.6849315 | H16: =F16-G16 -> 6.739726
F17: =F16/C16 -> 0.0084246575 | H17: =H16/C16 -> 0.006739726
B18: Annualized Yield | H18: =H17*(365/E16) -> 0.082
B20: Delta (Gross) | C20: =D10-D16 -> 0.0025
B21: Delta (Net) | C21: =H12-H18 -> 0.002
B23: Period (days) | C23: 365
B24: Note: All amounts mentioned in PKR mn unless stated otherwise.
B52: National Credit Guarantee Company Limited
B53: Investments Team | G53: Date: | H53: =today() -> 46109
B55: Proposed Transaction
B56: Mutual Fund Placement
C57: Placement | D57: Rate | E57: Days | F57: Gross | G57: Tax | H57: Net
B58: MCB Investment Savings Plan I | C58: =C67 -> 1303 | D58: 0.105 | E58: 30 | F58: =C58*(D58*E58/C72) -> 11.245068 | G58: =F58*25% -> 2.8112671 | H58: =F58-G58 -> 8.4338014
F59: =F58/C58 -> 0.008630137 | H59: =H58/C58 -> 0.0064726027
B60: Annualized Yield (Post Tax) | H60: =H59*(365/E58) -> 0.07875
B62: Status Quo
C63: Placement | D63: Rate | E63: Days | F63: Gross | G63: Tax | H63: Net
B64: Faysal Bank Limited | C64: 170 | D64: 0.1025 | E64: 30 | F64: =C64*(D64*E64/C72) -> 1.4321918 | G64: =F64*29% -> 0.41533562 | H64: =F64-G64 -> 1.0168562
B65: Alfalah Govt. Securities Fund | C65: 823 | D65: 0.0887 | E65: 30 | F65: =C65*(D65*E65/C72) -> 6.0000082 | G65: =F65*25% -> 1.5000021 | H65: =F65-G65 -> 4.5000062
B66: Alfalah MTS Fund | C66: 310 | D66: 0.092 | E66: 30 | F66: =C66*(D66*E66/C72) -> 2.3441096 | G66: =F66*25% -> 0.5860274 | H66: =F66-G66 -> 1.7580822
C67: =C64+C65+C66 -> 1303 | H67: =(H64+H65+H66)/C67 -> 0.0055832268
B68: Annualized Yield (Post Tax) | H68: =H67*(365/E66) -> 0.067929259
B70: Delta (Net) | C70: =D58-D64 -> 0.0025
B71: Delta (Net) - Annualized | C71: =H60-H68 -> 0.010820741
B72: Period (days) | C72: 365
B73: Note: All amounts mentioned in PKR mn unless stated otherwise.

Sheet Strategy Post Allocation
G2: Date | H2: =Today() -> 46109
B3: Post Allocation
B4: Instrument | C4: Exisiting Placement (PKR) | D4: Date of Placement | E4: Date of Maturity | F4: Rate | G4: Days to Maturity | H4: Remaining Days | I4: Concentration (%)
B5: MTBs (1Y) | C5: 2000000000 | D5: 45895 | E5: 46240 | F5: 0.1088 | G5: =E5-D5 -> 345 | H5: =E5-$H$2 -> 131 | I5: =C5/$C$19 -> 0.21634585
B6: MTBs (6M) | C6: 500000000 | D6: 46002 | E6: 46184 | F6: 0.1092 | G6: =E6-D6 -> 182 | H6: =E6-$H$2 -> 75 | I6: =C6/$C$19 -> 0.054086462
B7: MTBs (1Y) | C7: 1200000000 | D7: 46072 | E7: =D7+364 -> 46436 | F7: 0.1055 | G7: =E7-D7 -> 364 | H7: =E7-$H$2 -> 327 | I7: =C7/$C$19 -> 0.12980751
B8: Faysal Bank | C8: 261777528 | F8: 0.1025 | G8: 1 | H8: 1 | I8: =C8/$C$19 -> 0.02831724
B9: COI | C9: 1300000000 | D9: 46082 | E9: 46112 | F9: 0.1005 | G9: 30 | H9: =E9-H2 -> 3 | I9: =C9/$C$19 -> 0.1406248
B10: Alfalah Government Securities Fund Plan II* | C10: 816606719 | F10: 0.1 | G10: =0.78*365 -> 284.7 | H10: =1*G10 -> 284.7 | I10: =C10/$C$19 -> 0.088334736 | L10: 100 | N10: 0.15
B11: Alfalah MTS Fund (Formerly: Faysal MTS Fund)* | C11: 303753987 | F11: 0.102 | G11: 1 | H11: =1*G11 -> 1 | I11: =C11/$C$19 -> 0.032857957 | L11: 0.1025 | M11: =$L$10*(L11*(90/365)) -> 2.5273973 | N11: =M11*$N$10 -> 0.37910959 | O11: =M11-N11 -> 2.1482877 | P11: =M11+L10 -> 102.5274 | R11: 0.15
B12: Alfalah Income Multiplier* | C12: 500000000 | F12: 0.102 | G12: =0.22*365 -> 80.3 | H12: =1*G12 -> 80.3 | I12: =C12/$C$19 -> 0.054086462 | L12: 0.105 | M12: =P11*(L12*(90/365)) -> 2.6544765 | N12: =M12*$N$10 -> 0.39817147 | O12: =M12-N12 -> 2.256305 | P12: =P11+M12 -> 105.18187 | Q12: =P11*L11*(90/365) -> 2.5912746
B13: MCB Investment Saving Plan I* | C13: 800000000 | F13: 0.1 | G13: 1 | H13: =1*G13 -> 1 | I13: =C13/$C$19 -> 0.086538339 | L13: 0.1075 | M13: =P12*(L13*(90/365)) -> 2.7880401 | N13: =M13*$N$10 -> 0.41820601 | O13: =M13-N13 -> 2.3698341 | P13: =P12+M13 -> 107.96991
B14: Daewoo Short Term SUKUK | C14: 275000000 | D14: 45713 | E14: =D14+180 -> 45893 | F14: 0.1309 | G14: =E14-D14 -> 180 | H14: =E14-$H$2 -> -216 | I14: =C14/$C$19 -> 0.029747554 | L14: 0.11 | M14: =P13*(L14*(90/365)) -> 2.928499 | N14: =M14*$N$10 -> 0.43927485 | O14: =M14-N14 -> 2.4892242 | P14: =P13+M14 -> 110.89841
B15: Reallocation | M15: =SUM(M11:M14) -> 10.898413 | N15: =M15*N14 -> 4.7873987 | O15: =M15-N15 -> 6.1110141 | P15: =P14+L14 -> 111.00841
B16: MTBs (1Y) * | C16: 384022350 | D16: 46086 | E16: =D16+364 -> 46450 | F16: 0.107 | G16: =E16-D16 -> 364 | H16: =E16-D16 -> 364 | I16: =C16/$C$19 -> 0.04154082 | P16: =P15/L10 -> 1.1100841
B17: MTBs (1Y) * | C17: 451587500 | D17: 46086 | E17: =D17+364 -> 46450 | F17: 0.1072 | G17: =E17-D17 -> 364 | H17: =E17-D17 -> 364 | I17: =C17/$C$19 -> 0.04884954
B18: MTBs (1Y) * | C18: 451709500 | D18: 46086 | E18: =D18+364 -> 46450 | F18: =10.75% -> 0.1075 | G18: =E18-D18 -> 364 | H18: =E18-D18 -> 364 | I18: =C18/$C$19 -> 0.048862737 | P18: =P16-1 -> 0.11008413
B19: Total | C19: =SUM(C5:C14)+C16+C17+C18 -> 9244457584 | F19: =sumproduct(F5:F18,I5:I18) -> 0.10535855 | G19: =sumproduct(G5:G18,I5:I18) -> 221.63417 | H19: =sumproduct(H5:H18,I5:I18) -> 149.16913 | I19: =SUM(I5:I18) -> 1
B20: *Expected Rate on the Treasury Bills based on Auction
B21: Pre Allocation
B22: Instrument | C22: Exisiting Placement (PKR) | D22: Date of Placement | E22: Date of Maturity | F22: Rate | G22: Days to Maturity | H22: Remaining Days | I22: Concentration (%)
B23: MTBs (1Y) | C23: 2000000000 | D23: 45895 | E23: 46240 | F23: 0.1088 | G23: =E23-D23 -> 345 | H23: =E23-$H$2 -> 131 | I23: =C23/$C$19 -> 0.21634585
B24: MTBs (3M) | C24: 500000000 | D24: 46002 | E24: 46086 | F24: 0.1092 | G24: =E24-D24 -> 84 | H24: =E24-$H$2 -> -23 | I24: =C24/$C$19 -> 0.054086462
B25: MTBs (6M) | C25: 500000000 | D25: 46002 | E25: 46184 | F25: 0.1092 | G25: =E25-D25 -> 182 | H25: =E25-$H$2 -> 75 | I25: =C25/$C$19 -> 0.054086462
B26: Faysal Bank | C26: =2500000000+24096878 -> 2524096878 | F26: 0.1025 | G26: 1 | H26: 1 | I26: =C26/$C$19 -> 0.27303894
B27: COI | C27: 1300000000 | D27: 46051 | E27: 46081 | F27: 0.1005 | G27: 30 | H27: =E27-$H$2 -> -28 | I27: =C27/$C$19 -> 0.1406248
B28: Alfalah Government Securities Fund Plan II* | C28: 816606719 | F28: 0.1 | G28: 1 | H28: 1 | I28: =C28/$C$19 -> 0.088334736
B29: Alfalah MTS Fund (Formerly: Faysal MTS Fund)* | C29: 303753987 | F29: 0.1015 | G29: 1 | H29: 1 | I29: =C29/$C$19 -> 0.032857957
B30: Alfalah Income Multiplier* | C30: 500000000 | F30: 0.102 | G30: 1 | H30: 1 | I30: =C30/$C$19 -> 0.054086462
B31: MCB Investment Saving Plan I* | C31: 800000000 | F31: 0.1 | G31: 1 | H31: 1 | I31: =C31/$C$19 -> 0.086538339
B32: Total | C32: =sum(C23:C31) -> 9244457584 | F32: =sumproduct(F23:F31,I23:I31) -> 0.1038094 | G32: =sumproduct(G23:G31,I23:I31) -> 93.779916 | H32: =sumproduct(H23:H31,I23:I31) -> 27.751164 | I32: =sum(I23:I31) -> 1

Sheet PKRV Rates
A1: Tenor | B1: 46100 | C1: 46105 | D1: 46106 | E1: 46107 | F1: 46108
A2: 1W | B2: 10.5 | C2: 10.49 | D2: 10.48 | E2: 10.5 | F2: 10.51
A3: 2W | B3: 10.58 | C3: 10.56 | D3: 10.56 | E3: 10.57 | F3: 10.61
A4: 1M | B4: 10.85 | C4: 10.82 | D4: 10.77 | E4: 10.77 | F4: 10.87
A5: 2M | B5: 11.03 | C5: 11.03 | D5: 11.01 | E5: 11.03 | F5: 11.08
A6: 3M | B6: 11.16 | C6: 11.16 | D6: 11.16 | E6: 11.18 | F6: 11.24
A7: 4M | B7: 11.28 | C7: 11.28 | D7: 11.28 | E7: 11.32 | F7: 11.41
A8: 6M | B8: 11.36 | C8: 11.34 | D8: 11.34 | E8: 11.44 | F8: 11.56
A9: 9M | B9: 11.67 | C9: 11.68 | D9: 11.69 | E9: 11.72 | F9: 11.9
A10: 1Y | B10: 11.63 | C10: 11.65 | D10: 11.66 | E10: 11.72 | F10: 11.88
A11: 2Y | B11: 11.58 | C11: 11.57 | D11: 11.57 | E11: 11.68 | F11: 12.37
A12: 3Y | B12: 11.55 | C12: 11.54 | D12: 11.53 | E12: 11.61 | F12: 12.4
... A21: 20Y | B21: 12.73 | C21: 12.76 | D21: 12.77 | E21: 12.88 | F21: 12.83

Sheet Log
A1: Timestamp | B1: Date | C1: Status
A2: 46108.524 | B2: 46108 | C2: No file found
A3: 46108.524 | B3: 46107 | C3: OK: PKRV2603202624816.csv (20 tenors)
A4: 46108.752 | B4: 46108 | C4: OK: PKRV2703202624821.csv (20 tenors)
A5: 46108.752 | B5: 46107 | C5: OK: PKRV2603202624816.csv (20 tenors)
A6: 46109.752 | B6: 46108 | C6: OK: PKRV2703202624821.csv (20 tenors)
A7: 46109.752 | B7: 46107 | C7: OK: PKRV2603202624816.csv (20 tenors)
A8: 46109.866 | B8: 46108 | C8: OK: PKRV2703202624821.csv (20 tenors)
A9: 46109.866 | B9: 46107 | C9: OK: PKRV2603202624816.csv (20 tenors)
A10: 46109.868 | B10: 46107 | C10: OK: PKRV2703202624821.csv (20 tenors)
A11: 46109.869 | B11: 46106 | C11: OK: PKRV2603202624816.csv (20 tenors)
A12: 46109.87 | B12: 46107 | C12: OK: PKRV2703202624821.csv (20 tenors)
A13: 46109.87 | B13: 46105 | C13: OK: PKRV2503202624809.csv (20 tenors)
... A71: 46109.894 | B71: 46108 | C71: OK: PKRV2703202624821.csv (20 tenors)

Sheet Config
A1: Key | B1: Value
A2: LAST_SERIAL | B2: 24821

Sheet MUFAP Data
A1: Sector | B1: Category | C1: Fund Name | D1: Rating | E1: NAV | F1: YTD | G1: MTD | H1: 1 Day | I1: 15 Days | J1: 30 Days | K1: 90 Days | L1: 180 Days | M1: 270 Days | N1: 365 Days | O1: 2 Years | P1: 3 Years | Q1: Date Fetched
A2: Open-End Funds | B2: Money Market (Annualized Return ) | C2: ABL Cash Fund | D2: AA+(f) | E2: N/A | F2: 46111 | G2: 11.0216 | H2: 10.03 | I2: 9.31 | J2: 9.93 | K2: 9.51 | L2: 9.31 | M2: 9.43 | N2: 9.93 | O2: 10.04 | P2: 10.56 | Q2: 15.04
A3: Open-End Funds | B3: Money Market (Annualized Return ) | C3: ABL Money Market Plan I | D3: AA+(f) | E3: N/A | F3: 46111 | G3: 10.7282 | H3: 9.53 | I3: 8.46 | J3: 8.83 | K3: 8.6 | L3: 8.49 | M3: 8.47 | N3: 9.27 | O3: 9.46 | P3: 10.11 | Q3: 14.61
A4: Open-End Funds | B4: Money Market (Annualized Return ) | C4: AKD Cash Fund | D4: AA+(f) | E4: N/A | F4: 46108 | G4: 55.8398 | H4: 10.01 | I4: 8.63 | J4: 6.79 | K4: 8.77 | L4: 8.79 | M4: 9.41 | N4: 10.06 | O4: 10.01 | P4: 10.36 | Q4: 14.86
A5: Open-End Funds | B5: Money Market (Annualized Return ) | C5: AL Habib Cash Fund | D5: AAA(f) | E5: N/A | F5: 46108 | G5: 109.1993 | H5: 10.15 | I5: 9.15 | J5: 7.92 | K5: 8.67 | L5: 9.16 | M5: 9.39 | N5: 9.95 | O5: 10.16 | P5: 10.55 | Q5: 14.83
A6: Open-End Funds | B6: Money Market (Annualized Return ) | C6: AL Habib Money Market Fund | D6: AAA(f) | E6: N/A | F6: 46108 | G6: 107.9552 | H6: 10.11 | I6: 9.12 | J6: 7.92 | K6: 8.62 | L6: 9.17 | M6: 9.39 | N6: 9.94 | O6: 10.11 | P6: 10.46 | Q6: 14.74
A7: Open-End Funds | B7: Money Market (Annualized Return ) | C7: Alfalah Cash Fund - II | D7: AA+(f) | E7: N/A | F7: 46109 | G7: 110.1617 | H7: 9.95 | I7: 9.74 | J7: 9.89 | K7: 9.91 | L7: 9.76 | M7: 9.95 | N7: 10.02 | O7: 9.95 | P7: 10.58 | Q7: 15.68
A8: Open-End Funds | B8: Money Market (Annualized Return ) | C8: Alfalah GHP Cash Fund | D8: AA+(f) | E8: Nil | F8: 46109 | G8: 539.7433 | H8: 9.41 | I8: 8.65 | J8: 8.32 | K8: 8.88 | L8: 8.66 | M8: 8.66 | N8: 9.12 | O8: 9.41 | P8: 9.87 | Q8: 14.31
A9: Open-End Funds | B9: Money Market (Annualized Return ) | C9: Alfalah GHP Money Market Fund | D9: AA+(f) | E9: N/A | F9: 46108 | G9: 106.3205 | H9: 9.97 | I9: 9.32 | J9: 9.2 | K9: 9.51 | L9: 9.3 | M9: 9.45 | N9: 9.85 | O9: 9.97 | P9: 10.41 | Q9: 14.92
A10: Open-End Funds | B10: Money Market (Annualized Return ) | C10: Alfalah Money Market Fund - II | D10: AA(f) | E10: N/A | F10: 46109 | G10: 111.151 | H10: 10.15 | I10: 9.88 | J10: 9.75 | K10: 9.77 | L10: 9.89 | M10: 10.93 | N10: 10.07 | O10: 10.15 | P10: 10.64 | Q10: 14.67
A11: Open-End Funds | B11: Money Market (Annualized Return ) | C11: Askari Cash Fund | D11: AA+(f) | E11: N/A | F11: 46109 | G11: 110.6747 | H11: 9.1 | I11: 8.9 | J11: 8.1 | K11: 9.12 | L11: 8.89 | M11: 8.69 | N11: 8.77 | O11: 9.1 | P11: 9.53 | Q11: 14
A12: Open-End Funds | B12: Money Market (Annualized Return ) | C12: Atlas Liquid Fund | D12: AA+(f) | E12: N/A | F12: 46109 | G12: 539.7838 | H12: 10.31 | I12: 9.13 | J12: 9.31 | K12: 9.32 | L12: 9.21 | M12: 9.5 | N12: 10.17 | O12: 10.31 | P12: 10.64 | Q12: 15.22
A13: Open-End Funds | B13: Money Market (Annualized Return ) | C13: Atlas Money Market Fund | D13: AA+(f) | E13: N/A | F13: 46108 | G13: 552.0045 | H13: 10.4 | I13: 9.18 | J13: 8.69 | K13: 9.32 | L13: 9.26 | M13: 9.53 | N13: 10.18 | O13: 10.4 | P13: 10.73 | Q13: 15.28
... A19: Open-End Funds | B19: Money Market (Annualized Return ) | C19: MCB Cash Management Optimizer | D19: AA+(f) | E19: N/A | F19: 46111 | G19: 109.8664 | H19: 9.88 | I19: 8.89 | J19: 9.09 | K19: 8.91 | L19: 8.9 | M19: 9.27 | N19: 9.73 | O19: 9.87 | P19: 10.28 | Q19: 14.93
